2015-04-16 15:46:27,825 [Thread-7:9748] [django.request:226] [base:handle_uncaught_exception] [ERROR]- Internal Server Error: /en/myapp
Traceback (most recent call last):
  File "C:\Python27\lib\site-packages\django\core\handlers\base.py", line 114, in get_response
    response = wrapped_callback(request, *callback_args, **callback_kwargs)
  File "C:\Python27\lib\site-packages\django\views\generic\base.py", line 69, in view
    return self.dispatch(request, *args, **kwargs)
  File "C:\Python27\lib\site-packages\django\views\generic\base.py", line 87, in dispatch
    return handler(request, *args, **kwargs)
  File "C:\Python27\lib\site-packages\django\views\generic\base.py", line 189, in get
    url = self.get_redirect_url(*args, **kwargs)
  File "D:/webhome/django_scaffold/scaffold\scaffold\urls.py", line 11, in get_redirect_url
    real_url = re.sub(r'^/' + langReg, '', self.request.path_info)
NameError: global name 're' is not defined
2015-04-16 15:57:08,101 [Thread-7:8120] [django.request:226] [base:handle_uncaught_exception] [ERROR]- Internal Server Error: /myapp/
Traceback (most recent call last):
  File "C:\Python27\lib\site-packages\django\core\handlers\base.py", line 90, in get_response
    response = middleware_method(request)
  File "D:/webhome/django_scaffold/scaffold\scaffold\common\midLanguageDetect.py", line 46, in process_request
    request.session[cookie_name] = language_code
AttributeError: 'WSGIRequest' object has no attribute 'session'
2015-04-16 15:57:09,108 [Thread-7:8120] [django.request:226] [base:handle_uncaught_exception] [ERROR]- Internal Server Error: /myapp/
Traceback (most recent call last):
  File "C:\Python27\lib\site-packages\django\core\handlers\base.py", line 201, in get_response
    response = middleware_method(request, response)
  File "D:/webhome/django_scaffold/scaffold\scaffold\common\midLanguageDetect.py", line 51, in process_response
    if not cookie or cookie != request.session.get(cookie_name):
AttributeError: 'WSGIRequest' object has no attribute 'session'
2015-04-17 11:15:33,066 [Thread-7:9076] [django.request:226] [base:handle_uncaught_exception] [ERROR]- Internal Server Error: /
Traceback (most recent call last):
  File "C:\Python27\lib\site-packages\django\core\handlers\base.py", line 90, in get_response
    response = middleware_method(request)
  File "D:/webhome/django_scaffold/scaffold\scaffold\common\midware_language_detect.py", line 40, in process_request
    elif cookie_name in request.session.keys():
AttributeError: 'WSGIRequest' object has no attribute 'session'
2015-04-17 11:15:33,303 [Thread-7:9076] [django.request:226] [base:handle_uncaught_exception] [ERROR]- Internal Server Error: /
Traceback (most recent call last):
  File "C:\Python27\lib\site-packages\django\core\handlers\base.py", line 201, in get_response
    response = middleware_method(request, response)
  File "D:/webhome/django_scaffold/scaffold\scaffold\common\midware_language_detect.py", line 52, in process_response
    response.set_cookie(cookie_name, request.session.get(cookie_name))
AttributeError: 'WSGIRequest' object has no attribute 'session'
2015-04-17 11:15:35,615 [Thread-8:5872] [django.request:226] [base:handle_uncaught_exception] [ERROR]- Internal Server Error: /favicon.ico
Traceback (most recent call last):
  File "C:\Python27\lib\site-packages\django\core\handlers\base.py", line 90, in get_response
    response = middleware_method(request)
  File "D:/webhome/django_scaffold/scaffold\scaffold\common\midware_language_detect.py", line 40, in process_request
    elif cookie_name in request.session.keys():
AttributeError: 'WSGIRequest' object has no attribute 'session'
2015-04-17 11:15:35,822 [Thread-8:5872] [django.request:226] [base:handle_uncaught_exception] [ERROR]- Internal Server Error: /favicon.ico
Traceback (most recent call last):
  File "C:\Python27\lib\site-packages\django\core\handlers\base.py", line 201, in get_response
    response = middleware_method(request, response)
  File "D:/webhome/django_scaffold/scaffold\scaffold\common\midware_language_detect.py", line 52, in process_response
    response.set_cookie(cookie_name, request.session.get(cookie_name))
AttributeError: 'WSGIRequest' object has no attribute 'session'
2015-04-17 11:16:41,759 [Thread-7:10368] [django.request:226] [base:handle_uncaught_exception] [ERROR]- Internal Server Error: /
Traceback (most recent call last):
  File "C:\Python27\lib\site-packages\django\core\handlers\base.py", line 90, in get_response
    response = middleware_method(request)
  File "D:/webhome/django_scaffold/scaffold\scaffold\common\midware_language_detect.py", line 40, in process_request
    elif cookie_name in request.session.keys():
AttributeError: 'WSGIRequest' object has no attribute 'session'
2015-04-17 11:16:41,983 [Thread-7:10368] [django.request:226] [base:handle_uncaught_exception] [ERROR]- Internal Server Error: /
Traceback (most recent call last):
  File "C:\Python27\lib\site-packages\django\core\handlers\base.py", line 201, in get_response
    response = middleware_method(request, response)
  File "D:/webhome/django_scaffold/scaffold\scaffold\common\midware_language_detect.py", line 52, in process_response
    response.set_cookie(cookie_name, request.session.get(cookie_name))
AttributeError: 'WSGIRequest' object has no attribute 'session'
2015-04-17 11:16:42,437 [Thread-8:10548] [django.request:226] [base:handle_uncaught_exception] [ERROR]- Internal Server Error: /favicon.ico
Traceback (most recent call last):
  File "C:\Python27\lib\site-packages\django\core\handlers\base.py", line 90, in get_response
    response = middleware_method(request)
  File "D:/webhome/django_scaffold/scaffold\scaffold\common\midware_language_detect.py", line 40, in process_request
    elif cookie_name in request.session.keys():
AttributeError: 'WSGIRequest' object has no attribute 'session'
2015-04-17 11:16:42,671 [Thread-8:10548] [django.request:226] [base:handle_uncaught_exception] [ERROR]- Internal Server Error: /favicon.ico
Traceback (most recent call last):
  File "C:\Python27\lib\site-packages\django\core\handlers\base.py", line 201, in get_response
    response = middleware_method(request, response)
  File "D:/webhome/django_scaffold/scaffold\scaffold\common\midware_language_detect.py", line 52, in process_response
    response.set_cookie(cookie_name, request.session.get(cookie_name))
AttributeError: 'WSGIRequest' object has no attribute 'session'
2015-04-17 11:18:12,056 [Thread-7:7696] [django.request:226] [base:handle_uncaught_exception] [ERROR]- Internal Server Error: /
Traceback (most recent call last):
  File "C:\Python27\lib\site-packages\django\core\handlers\base.py", line 90, in get_response
    response = middleware_method(request)
  File "D:/webhome/django_scaffold/scaffold\scaffold\common\midware_language_detect.py", line 40, in process_request
    elif cookie_name in request.session.keys():
AttributeError: 'WSGIRequest' object has no attribute 'session'
2015-04-17 11:18:12,382 [Thread-8:7796] [django.request:226] [base:handle_uncaught_exception] [ERROR]- Internal Server Error: /favicon.ico
Traceback (most recent call last):
  File "C:\Python27\lib\site-packages\django\core\handlers\base.py", line 90, in get_response
    response = middleware_method(request)
  File "D:/webhome/django_scaffold/scaffold\scaffold\common\midware_language_detect.py", line 40, in process_request
    elif cookie_name in request.session.keys():
AttributeError: 'WSGIRequest' object has no attribute 'session'
2015-04-17 11:20:24,563 [Thread-7:5704] [django.request:226] [base:handle_uncaught_exception] [ERROR]- Internal Server Error: /
Traceback (most recent call last):
  File "C:\Python27\lib\site-packages\django\core\handlers\base.py", line 90, in get_response
    response = middleware_method(request)
  File "D:/webhome/django_scaffold/scaffold\scaffold\common\midware_language_detect.py", line 43, in process_request
    language_code = self.get_browser_language(request)
  File "D:/webhome/django_scaffold/scaffold\scaffold\common\midware_language_detect.py", line 29, in get_browser_language
    if self.is_supported_language(language_code):
  File "D:/webhome/django_scaffold/scaffold\scaffold\common\midware_language_detect.py", line 19, in is_supported_language
    supported_languages = dict(settings.LANGUAGES).keys()
AttributeError: 'module' object has no attribute 'LANGUAGES'
2015-04-17 11:20:25,109 [Thread-8:10668] [django.request:226] [base:handle_uncaught_exception] [ERROR]- Internal Server Error: /favicon.ico
Traceback (most recent call last):
  File "C:\Python27\lib\site-packages\django\core\handlers\base.py", line 90, in get_response
    response = middleware_method(request)
  File "D:/webhome/django_scaffold/scaffold\scaffold\common\midware_language_detect.py", line 43, in process_request
    language_code = self.get_browser_language(request)
  File "D:/webhome/django_scaffold/scaffold\scaffold\common\midware_language_detect.py", line 29, in get_browser_language
    if self.is_supported_language(language_code):
  File "D:/webhome/django_scaffold/scaffold\scaffold\common\midware_language_detect.py", line 19, in is_supported_language
    supported_languages = dict(settings.LANGUAGES).keys()
AttributeError: 'module' object has no attribute 'LANGUAGES'
2015-04-17 11:22:25,367 [Thread-7:2360] [django.request:145] [base:get_response] [WARNING]- Not Found: /
2015-04-17 11:22:25,457 [Thread-8:4892] [django.request:145] [base:get_response] [WARNING]- Not Found: /favicon.ico
2015-04-17 11:22:31,539 [Thread-9:5056] [django.request:145] [base:get_response] [WARNING]- Not Found: /welcome
2015-04-17 11:22:38,571 [Thread-10:9160] [django.request:145] [base:get_response] [WARNING]- Not Found: /
2015-04-17 11:22:55,698 [Thread-19:10396] [django.request:145] [base:get_response] [WARNING]- Not Found: /en/myapp/
2015-04-17 14:47:46,019 [Thread-23:2360] [django.request:145] [base:get_response] [WARNING]- Not Found: /
2015-04-17 14:47:57,447 [Thread-27:10076] [django.request:145] [base:get_response] [WARNING]- Not Found: /en/myapp/
2015-04-17 14:48:52,490 [Thread-30:11724] [django.request:145] [base:get_response] [WARNING]- Not Found: /en/myapp/
2015-04-17 15:04:17,480 [Thread-7:12736] [django.request:226] [base:handle_uncaught_exception] [ERROR]- Internal Server Error: /
Traceback (most recent call last):
  File "C:\Python27\lib\site-packages\django\core\handlers\base.py", line 90, in get_response
    response = middleware_method(request)
  File "D:/webhome/django_scaffold/scaffold\scaffold\common\midware_language_detect.py", line 46, in process_request
    request.session[cookie_name] = language_code
  File "C:\Python27\lib\site-packages\django\contrib\sessions\backends\base.py", line 50, in __setitem__
    self._session[key] = value
  File "C:\Python27\lib\site-packages\django\contrib\sessions\backends\base.py", line 173, in _get_session
    self._session_cache = self.load()
  File "C:\Python27\lib\site-packages\django\contrib\sessions\backends\db.py", line 20, in load
    expire_date__gt=timezone.now()
  File "C:\Python27\lib\site-packages\django\db\models\manager.py", line 152, in get
    return self.get_queryset().get(*args, **kwargs)
  File "C:\Python27\lib\site-packages\django\db\models\query.py", line 301, in get
    num = len(clone)
  File "C:\Python27\lib\site-packages\django\db\models\query.py", line 77, in __len__
    self._fetch_all()
  File "C:\Python27\lib\site-packages\django\db\models\query.py", line 854, in _fetch_all
    self._result_cache = list(self.iterator())
  File "C:\Python27\lib\site-packages\django\db\models\query.py", line 220, in iterator
    for row in compiler.results_iter():
  File "C:\Python27\lib\site-packages\django\db\models\sql\compiler.py", line 710, in results_iter
    for rows in self.execute_sql(MULTI):
  File "C:\Python27\lib\site-packages\django\db\models\sql\compiler.py", line 781, in execute_sql
    cursor.execute(sql, params)
  File "C:\Python27\lib\site-packages\django\db\backends\util.py", line 53, in execute
    return self.cursor.execute(sql, params)
  File "C:\Python27\lib\site-packages\django\db\utils.py", line 99, in __exit__
    six.reraise(dj_exc_type, dj_exc_value, traceback)
  File "C:\Python27\lib\site-packages\django\db\backends\util.py", line 53, in execute
    return self.cursor.execute(sql, params)
  File "C:\Python27\lib\site-packages\django\db\backends\sqlite3\base.py", line 450, in execute
    return Database.Cursor.execute(self, query, params)
OperationalError: no such table: django_session
2015-04-17 15:04:17,516 [Thread-7:12736] [django.request:226] [base:handle_uncaught_exception] [ERROR]- Internal Server Error: /
Traceback (most recent call last):
  File "C:\Python27\lib\site-packages\django\core\handlers\base.py", line 201, in get_response
    response = middleware_method(request, response)
  File "D:/webhome/django_scaffold/scaffold\scaffold\common\midware_language_detect.py", line 51, in process_response
    if not cookie or cookie != request.session.get(cookie_name):
  File "C:\Python27\lib\site-packages\django\contrib\sessions\backends\base.py", line 58, in get
    return self._session.get(key, default)
  File "C:\Python27\lib\site-packages\django\contrib\sessions\backends\base.py", line 173, in _get_session
    self._session_cache = self.load()
  File "C:\Python27\lib\site-packages\django\contrib\sessions\backends\db.py", line 20, in load
    expire_date__gt=timezone.now()
  File "C:\Python27\lib\site-packages\django\db\models\manager.py", line 152, in get
    return self.get_queryset().get(*args, **kwargs)
  File "C:\Python27\lib\site-packages\django\db\models\query.py", line 301, in get
    num = len(clone)
  File "C:\Python27\lib\site-packages\django\db\models\query.py", line 77, in __len__
    self._fetch_all()
  File "C:\Python27\lib\site-packages\django\db\models\query.py", line 854, in _fetch_all
    self._result_cache = list(self.iterator())
  File "C:\Python27\lib\site-packages\django\db\models\query.py", line 220, in iterator
    for row in compiler.results_iter():
  File "C:\Python27\lib\site-packages\django\db\models\sql\compiler.py", line 710, in results_iter
    for rows in self.execute_sql(MULTI):
  File "C:\Python27\lib\site-packages\django\db\models\sql\compiler.py", line 781, in execute_sql
    cursor.execute(sql, params)
  File "C:\Python27\lib\site-packages\django\db\backends\util.py", line 53, in execute
    return self.cursor.execute(sql, params)
  File "C:\Python27\lib\site-packages\django\db\utils.py", line 99, in __exit__
    six.reraise(dj_exc_type, dj_exc_value, traceback)
  File "C:\Python27\lib\site-packages\django\db\backends\util.py", line 53, in execute
    return self.cursor.execute(sql, params)
  File "C:\Python27\lib\site-packages\django\db\backends\sqlite3\base.py", line 450, in execute
    return Database.Cursor.execute(self, query, params)
OperationalError: no such table: django_session
2015-04-17 15:04:24,500 [Thread-8:12240] [django.request:226] [base:handle_uncaught_exception] [ERROR]- Internal Server Error: /en/myapp
Traceback (most recent call last):
  File "C:\Python27\lib\site-packages\django\core\handlers\base.py", line 90, in get_response
    response = middleware_method(request)
  File "D:/webhome/django_scaffold/scaffold\scaffold\common\midware_language_detect.py", line 46, in process_request
    request.session[cookie_name] = language_code
  File "C:\Python27\lib\site-packages\django\contrib\sessions\backends\base.py", line 50, in __setitem__
    self._session[key] = value
  File "C:\Python27\lib\site-packages\django\contrib\sessions\backends\base.py", line 173, in _get_session
    self._session_cache = self.load()
  File "C:\Python27\lib\site-packages\django\contrib\sessions\backends\db.py", line 20, in load
    expire_date__gt=timezone.now()
  File "C:\Python27\lib\site-packages\django\db\models\manager.py", line 152, in get
    return self.get_queryset().get(*args, **kwargs)
  File "C:\Python27\lib\site-packages\django\db\models\query.py", line 301, in get
    num = len(clone)
  File "C:\Python27\lib\site-packages\django\db\models\query.py", line 77, in __len__
    self._fetch_all()
  File "C:\Python27\lib\site-packages\django\db\models\query.py", line 854, in _fetch_all
    self._result_cache = list(self.iterator())
  File "C:\Python27\lib\site-packages\django\db\models\query.py", line 220, in iterator
    for row in compiler.results_iter():
  File "C:\Python27\lib\site-packages\django\db\models\sql\compiler.py", line 710, in results_iter
    for rows in self.execute_sql(MULTI):
  File "C:\Python27\lib\site-packages\django\db\models\sql\compiler.py", line 781, in execute_sql
    cursor.execute(sql, params)
  File "C:\Python27\lib\site-packages\django\db\backends\util.py", line 53, in execute
    return self.cursor.execute(sql, params)
  File "C:\Python27\lib\site-packages\django\db\utils.py", line 99, in __exit__
    six.reraise(dj_exc_type, dj_exc_value, traceback)
  File "C:\Python27\lib\site-packages\django\db\backends\util.py", line 53, in execute
    return self.cursor.execute(sql, params)
  File "C:\Python27\lib\site-packages\django\db\backends\sqlite3\base.py", line 450, in execute
    return Database.Cursor.execute(self, query, params)
OperationalError: no such table: django_session
2015-04-17 15:04:24,503 [Thread-8:12240] [django.request:226] [base:handle_uncaught_exception] [ERROR]- Internal Server Error: /en/myapp
Traceback (most recent call last):
  File "C:\Python27\lib\site-packages\django\core\handlers\base.py", line 201, in get_response
    response = middleware_method(request, response)
  File "D:/webhome/django_scaffold/scaffold\scaffold\common\midware_language_detect.py", line 51, in process_response
    if not cookie or cookie != request.session.get(cookie_name):
  File "C:\Python27\lib\site-packages\django\contrib\sessions\backends\base.py", line 58, in get
    return self._session.get(key, default)
  File "C:\Python27\lib\site-packages\django\contrib\sessions\backends\base.py", line 173, in _get_session
    self._session_cache = self.load()
  File "C:\Python27\lib\site-packages\django\contrib\sessions\backends\db.py", line 20, in load
    expire_date__gt=timezone.now()
  File "C:\Python27\lib\site-packages\django\db\models\manager.py", line 152, in get
    return self.get_queryset().get(*args, **kwargs)
  File "C:\Python27\lib\site-packages\django\db\models\query.py", line 301, in get
    num = len(clone)
  File "C:\Python27\lib\site-packages\django\db\models\query.py", line 77, in __len__
    self._fetch_all()
  File "C:\Python27\lib\site-packages\django\db\models\query.py", line 854, in _fetch_all
    self._result_cache = list(self.iterator())
  File "C:\Python27\lib\site-packages\django\db\models\query.py", line 220, in iterator
    for row in compiler.results_iter():
  File "C:\Python27\lib\site-packages\django\db\models\sql\compiler.py", line 710, in results_iter
    for rows in self.execute_sql(MULTI):
  File "C:\Python27\lib\site-packages\django\db\models\sql\compiler.py", line 781, in execute_sql
    cursor.execute(sql, params)
  File "C:\Python27\lib\site-packages\django\db\backends\util.py", line 53, in execute
    return self.cursor.execute(sql, params)
  File "C:\Python27\lib\site-packages\django\db\utils.py", line 99, in __exit__
    six.reraise(dj_exc_type, dj_exc_value, traceback)
  File "C:\Python27\lib\site-packages\django\db\backends\util.py", line 53, in execute
    return self.cursor.execute(sql, params)
  File "C:\Python27\lib\site-packages\django\db\backends\sqlite3\base.py", line 450, in execute
    return Database.Cursor.execute(self, query, params)
OperationalError: no such table: django_session
2015-04-17 15:04:31,154 [Thread-9:12104] [django.request:226] [base:handle_uncaught_exception] [ERROR]- Internal Server Error: /
Traceback (most recent call last):
  File "C:\Python27\lib\site-packages\django\core\handlers\base.py", line 90, in get_response
    response = middleware_method(request)
  File "D:/webhome/django_scaffold/scaffold\scaffold\common\midware_language_detect.py", line 46, in process_request
    request.session[cookie_name] = language_code
  File "C:\Python27\lib\site-packages\django\contrib\sessions\backends\base.py", line 50, in __setitem__
    self._session[key] = value
  File "C:\Python27\lib\site-packages\django\contrib\sessions\backends\base.py", line 173, in _get_session
    self._session_cache = self.load()
  File "C:\Python27\lib\site-packages\django\contrib\sessions\backends\db.py", line 20, in load
    expire_date__gt=timezone.now()
  File "C:\Python27\lib\site-packages\django\db\models\manager.py", line 152, in get
    return self.get_queryset().get(*args, **kwargs)
  File "C:\Python27\lib\site-packages\django\db\models\query.py", line 301, in get
    num = len(clone)
  File "C:\Python27\lib\site-packages\django\db\models\query.py", line 77, in __len__
    self._fetch_all()
  File "C:\Python27\lib\site-packages\django\db\models\query.py", line 854, in _fetch_all
    self._result_cache = list(self.iterator())
  File "C:\Python27\lib\site-packages\django\db\models\query.py", line 220, in iterator
    for row in compiler.results_iter():
  File "C:\Python27\lib\site-packages\django\db\models\sql\compiler.py", line 710, in results_iter
    for rows in self.execute_sql(MULTI):
  File "C:\Python27\lib\site-packages\django\db\models\sql\compiler.py", line 781, in execute_sql
    cursor.execute(sql, params)
  File "C:\Python27\lib\site-packages\django\db\backends\util.py", line 53, in execute
    return self.cursor.execute(sql, params)
  File "C:\Python27\lib\site-packages\django\db\utils.py", line 99, in __exit__
    six.reraise(dj_exc_type, dj_exc_value, traceback)
  File "C:\Python27\lib\site-packages\django\db\backends\util.py", line 53, in execute
    return self.cursor.execute(sql, params)
  File "C:\Python27\lib\site-packages\django\db\backends\sqlite3\base.py", line 450, in execute
    return Database.Cursor.execute(self, query, params)
OperationalError: no such table: django_session
2015-04-17 15:04:31,160 [Thread-9:12104] [django.request:226] [base:handle_uncaught_exception] [ERROR]- Internal Server Error: /
Traceback (most recent call last):
  File "C:\Python27\lib\site-packages\django\core\handlers\base.py", line 201, in get_response
    response = middleware_method(request, response)
  File "D:/webhome/django_scaffold/scaffold\scaffold\common\midware_language_detect.py", line 51, in process_response
    if not cookie or cookie != request.session.get(cookie_name):
  File "C:\Python27\lib\site-packages\django\contrib\sessions\backends\base.py", line 58, in get
    return self._session.get(key, default)
  File "C:\Python27\lib\site-packages\django\contrib\sessions\backends\base.py", line 173, in _get_session
    self._session_cache = self.load()
  File "C:\Python27\lib\site-packages\django\contrib\sessions\backends\db.py", line 20, in load
    expire_date__gt=timezone.now()
  File "C:\Python27\lib\site-packages\django\db\models\manager.py", line 152, in get
    return self.get_queryset().get(*args, **kwargs)
  File "C:\Python27\lib\site-packages\django\db\models\query.py", line 301, in get
    num = len(clone)
  File "C:\Python27\lib\site-packages\django\db\models\query.py", line 77, in __len__
    self._fetch_all()
  File "C:\Python27\lib\site-packages\django\db\models\query.py", line 854, in _fetch_all
    self._result_cache = list(self.iterator())
  File "C:\Python27\lib\site-packages\django\db\models\query.py", line 220, in iterator
    for row in compiler.results_iter():
  File "C:\Python27\lib\site-packages\django\db\models\sql\compiler.py", line 710, in results_iter
    for rows in self.execute_sql(MULTI):
  File "C:\Python27\lib\site-packages\django\db\models\sql\compiler.py", line 781, in execute_sql
    cursor.execute(sql, params)
  File "C:\Python27\lib\site-packages\django\db\backends\util.py", line 53, in execute
    return self.cursor.execute(sql, params)
  File "C:\Python27\lib\site-packages\django\db\utils.py", line 99, in __exit__
    six.reraise(dj_exc_type, dj_exc_value, traceback)
  File "C:\Python27\lib\site-packages\django\db\backends\util.py", line 53, in execute
    return self.cursor.execute(sql, params)
  File "C:\Python27\lib\site-packages\django\db\backends\sqlite3\base.py", line 450, in execute
    return Database.Cursor.execute(self, query, params)
OperationalError: no such table: django_session
2015-04-17 15:06:51,713 [Thread-7:9680] [django.request:226] [base:handle_uncaught_exception] [ERROR]- Internal Server Error: /en/myapp/
Traceback (most recent call last):
  File "C:\Python27\lib\site-packages\django\core\handlers\base.py", line 90, in get_response
    response = middleware_method(request)
  File "D:/webhome/django_scaffold/scaffold\scaffold\common\midware_language_detect.py", line 46, in process_request
    request.session[cookie_name] = language_code
  File "C:\Python27\lib\site-packages\django\contrib\sessions\backends\base.py", line 50, in __setitem__
    self._session[key] = value
  File "C:\Python27\lib\site-packages\django\contrib\sessions\backends\base.py", line 173, in _get_session
    self._session_cache = self.load()
  File "C:\Python27\lib\site-packages\django\contrib\sessions\backends\db.py", line 20, in load
    expire_date__gt=timezone.now()
  File "C:\Python27\lib\site-packages\django\db\models\manager.py", line 152, in get
    return self.get_queryset().get(*args, **kwargs)
  File "C:\Python27\lib\site-packages\django\db\models\query.py", line 301, in get
    num = len(clone)
  File "C:\Python27\lib\site-packages\django\db\models\query.py", line 77, in __len__
    self._fetch_all()
  File "C:\Python27\lib\site-packages\django\db\models\query.py", line 854, in _fetch_all
    self._result_cache = list(self.iterator())
  File "C:\Python27\lib\site-packages\django\db\models\query.py", line 220, in iterator
    for row in compiler.results_iter():
  File "C:\Python27\lib\site-packages\django\db\models\sql\compiler.py", line 710, in results_iter
    for rows in self.execute_sql(MULTI):
  File "C:\Python27\lib\site-packages\django\db\models\sql\compiler.py", line 780, in execute_sql
    cursor = self.connection.cursor()
  File "C:\Python27\lib\site-packages\django\db\backends\__init__.py", line 157, in cursor
    cursor = self.make_debug_cursor(self._cursor())
  File "C:\Python27\lib\site-packages\django\db\backends\__init__.py", line 129, in _cursor
    self.ensure_connection()
  File "C:\Python27\lib\site-packages\django\db\backends\__init__.py", line 124, in ensure_connection
    self.connect()
  File "C:\Python27\lib\site-packages\django\db\utils.py", line 99, in __exit__
    six.reraise(dj_exc_type, dj_exc_value, traceback)
  File "C:\Python27\lib\site-packages\django\db\backends\__init__.py", line 124, in ensure_connection
    self.connect()
  File "C:\Python27\lib\site-packages\django\db\backends\__init__.py", line 112, in connect
    self.connection = self.get_new_connection(conn_params)
  File "C:\Python27\lib\site-packages\django\db\backends\mysql\base.py", line 435, in get_new_connection
    conn = Database.connect(**conn_params)
  File "C:\Python27\lib\site-packages\MySQLdb\__init__.py", line 81, in Connect
    return Connection(*args, **kwargs)
  File "C:\Python27\lib\site-packages\MySQLdb\connections.py", line 193, in __init__
    super(Connection, self).__init__(*args, **kwargs2)
OperationalError: (1049, "Unknown database '<database_name>'")
2015-04-17 15:06:52,292 [Thread-7:9680] [django.request:226] [base:handle_uncaught_exception] [ERROR]- Internal Server Error: /en/myapp/
Traceback (most recent call last):
  File "C:\Python27\lib\site-packages\django\core\handlers\base.py", line 201, in get_response
    response = middleware_method(request, response)
  File "D:/webhome/django_scaffold/scaffold\scaffold\common\midware_language_detect.py", line 51, in process_response
    if not cookie or cookie != request.session.get(cookie_name):
  File "C:\Python27\lib\site-packages\django\contrib\sessions\backends\base.py", line 58, in get
    return self._session.get(key, default)
  File "C:\Python27\lib\site-packages\django\contrib\sessions\backends\base.py", line 173, in _get_session
    self._session_cache = self.load()
  File "C:\Python27\lib\site-packages\django\contrib\sessions\backends\db.py", line 20, in load
    expire_date__gt=timezone.now()
  File "C:\Python27\lib\site-packages\django\db\models\manager.py", line 152, in get
    return self.get_queryset().get(*args, **kwargs)
  File "C:\Python27\lib\site-packages\django\db\models\query.py", line 301, in get
    num = len(clone)
  File "C:\Python27\lib\site-packages\django\db\models\query.py", line 77, in __len__
    self._fetch_all()
  File "C:\Python27\lib\site-packages\django\db\models\query.py", line 854, in _fetch_all
    self._result_cache = list(self.iterator())
  File "C:\Python27\lib\site-packages\django\db\models\query.py", line 220, in iterator
    for row in compiler.results_iter():
  File "C:\Python27\lib\site-packages\django\db\models\sql\compiler.py", line 710, in results_iter
    for rows in self.execute_sql(MULTI):
  File "C:\Python27\lib\site-packages\django\db\models\sql\compiler.py", line 780, in execute_sql
    cursor = self.connection.cursor()
  File "C:\Python27\lib\site-packages\django\db\backends\__init__.py", line 157, in cursor
    cursor = self.make_debug_cursor(self._cursor())
  File "C:\Python27\lib\site-packages\django\db\backends\__init__.py", line 129, in _cursor
    self.ensure_connection()
  File "C:\Python27\lib\site-packages\django\db\backends\__init__.py", line 124, in ensure_connection
    self.connect()
  File "C:\Python27\lib\site-packages\django\db\utils.py", line 99, in __exit__
    six.reraise(dj_exc_type, dj_exc_value, traceback)
  File "C:\Python27\lib\site-packages\django\db\backends\__init__.py", line 124, in ensure_connection
    self.connect()
  File "C:\Python27\lib\site-packages\django\db\backends\__init__.py", line 112, in connect
    self.connection = self.get_new_connection(conn_params)
  File "C:\Python27\lib\site-packages\django\db\backends\mysql\base.py", line 435, in get_new_connection
    conn = Database.connect(**conn_params)
  File "C:\Python27\lib\site-packages\MySQLdb\__init__.py", line 81, in Connect
    return Connection(*args, **kwargs)
  File "C:\Python27\lib\site-packages\MySQLdb\connections.py", line 193, in __init__
    super(Connection, self).__init__(*args, **kwargs2)
OperationalError: (1049, "Unknown database '<database_name>'")
2015-04-17 15:07:37,713 [Thread-7:13156] [django.request:226] [base:handle_uncaught_exception] [ERROR]- Internal Server Error: /en/myapp/
Traceback (most recent call last):
  File "C:\Python27\lib\site-packages\django\core\handlers\base.py", line 90, in get_response
    response = middleware_method(request)
  File "D:/webhome/django_scaffold/scaffold\scaffold\common\midware_language_detect.py", line 46, in process_request
    request.session[cookie_name] = language_code
  File "C:\Python27\lib\site-packages\django\contrib\sessions\backends\base.py", line 50, in __setitem__
    self._session[key] = value
  File "C:\Python27\lib\site-packages\django\contrib\sessions\backends\base.py", line 173, in _get_session
    self._session_cache = self.load()
  File "C:\Python27\lib\site-packages\django\contrib\sessions\backends\db.py", line 20, in load
    expire_date__gt=timezone.now()
  File "C:\Python27\lib\site-packages\django\db\models\manager.py", line 152, in get
    return self.get_queryset().get(*args, **kwargs)
  File "C:\Python27\lib\site-packages\django\db\models\query.py", line 301, in get
    num = len(clone)
  File "C:\Python27\lib\site-packages\django\db\models\query.py", line 77, in __len__
    self._fetch_all()
  File "C:\Python27\lib\site-packages\django\db\models\query.py", line 854, in _fetch_all
    self._result_cache = list(self.iterator())
  File "C:\Python27\lib\site-packages\django\db\models\query.py", line 220, in iterator
    for row in compiler.results_iter():
  File "C:\Python27\lib\site-packages\django\db\models\sql\compiler.py", line 710, in results_iter
    for rows in self.execute_sql(MULTI):
  File "C:\Python27\lib\site-packages\django\db\models\sql\compiler.py", line 780, in execute_sql
    cursor = self.connection.cursor()
  File "C:\Python27\lib\site-packages\django\db\backends\__init__.py", line 157, in cursor
    cursor = self.make_debug_cursor(self._cursor())
  File "C:\Python27\lib\site-packages\django\db\backends\__init__.py", line 129, in _cursor
    self.ensure_connection()
  File "C:\Python27\lib\site-packages\django\db\backends\__init__.py", line 124, in ensure_connection
    self.connect()
  File "C:\Python27\lib\site-packages\django\db\utils.py", line 99, in __exit__
    six.reraise(dj_exc_type, dj_exc_value, traceback)
  File "C:\Python27\lib\site-packages\django\db\backends\__init__.py", line 124, in ensure_connection
    self.connect()
  File "C:\Python27\lib\site-packages\django\db\backends\__init__.py", line 112, in connect
    self.connection = self.get_new_connection(conn_params)
  File "C:\Python27\lib\site-packages\django\db\backends\mysql\base.py", line 435, in get_new_connection
    conn = Database.connect(**conn_params)
  File "C:\Python27\lib\site-packages\MySQLdb\__init__.py", line 81, in Connect
    return Connection(*args, **kwargs)
  File "C:\Python27\lib\site-packages\MySQLdb\connections.py", line 193, in __init__
    super(Connection, self).__init__(*args, **kwargs2)
OperationalError: (1049, "Unknown database 'thunderstrike'")
2015-04-17 15:07:38,246 [Thread-7:13156] [django.request:226] [base:handle_uncaught_exception] [ERROR]- Internal Server Error: /en/myapp/
Traceback (most recent call last):
  File "C:\Python27\lib\site-packages\django\core\handlers\base.py", line 201, in get_response
    response = middleware_method(request, response)
  File "D:/webhome/django_scaffold/scaffold\scaffold\common\midware_language_detect.py", line 51, in process_response
    if not cookie or cookie != request.session.get(cookie_name):
  File "C:\Python27\lib\site-packages\django\contrib\sessions\backends\base.py", line 58, in get
    return self._session.get(key, default)
  File "C:\Python27\lib\site-packages\django\contrib\sessions\backends\base.py", line 173, in _get_session
    self._session_cache = self.load()
  File "C:\Python27\lib\site-packages\django\contrib\sessions\backends\db.py", line 20, in load
    expire_date__gt=timezone.now()
  File "C:\Python27\lib\site-packages\django\db\models\manager.py", line 152, in get
    return self.get_queryset().get(*args, **kwargs)
  File "C:\Python27\lib\site-packages\django\db\models\query.py", line 301, in get
    num = len(clone)
  File "C:\Python27\lib\site-packages\django\db\models\query.py", line 77, in __len__
    self._fetch_all()
  File "C:\Python27\lib\site-packages\django\db\models\query.py", line 854, in _fetch_all
    self._result_cache = list(self.iterator())
  File "C:\Python27\lib\site-packages\django\db\models\query.py", line 220, in iterator
    for row in compiler.results_iter():
  File "C:\Python27\lib\site-packages\django\db\models\sql\compiler.py", line 710, in results_iter
    for rows in self.execute_sql(MULTI):
  File "C:\Python27\lib\site-packages\django\db\models\sql\compiler.py", line 780, in execute_sql
    cursor = self.connection.cursor()
  File "C:\Python27\lib\site-packages\django\db\backends\__init__.py", line 157, in cursor
    cursor = self.make_debug_cursor(self._cursor())
  File "C:\Python27\lib\site-packages\django\db\backends\__init__.py", line 129, in _cursor
    self.ensure_connection()
  File "C:\Python27\lib\site-packages\django\db\backends\__init__.py", line 124, in ensure_connection
    self.connect()
  File "C:\Python27\lib\site-packages\django\db\utils.py", line 99, in __exit__
    six.reraise(dj_exc_type, dj_exc_value, traceback)
  File "C:\Python27\lib\site-packages\django\db\backends\__init__.py", line 124, in ensure_connection
    self.connect()
  File "C:\Python27\lib\site-packages\django\db\backends\__init__.py", line 112, in connect
    self.connection = self.get_new_connection(conn_params)
  File "C:\Python27\lib\site-packages\django\db\backends\mysql\base.py", line 435, in get_new_connection
    conn = Database.connect(**conn_params)
  File "C:\Python27\lib\site-packages\MySQLdb\__init__.py", line 81, in Connect
    return Connection(*args, **kwargs)
  File "C:\Python27\lib\site-packages\MySQLdb\connections.py", line 193, in __init__
    super(Connection, self).__init__(*args, **kwargs2)
OperationalError: (1049, "Unknown database 'thunderstrike'")
2015-04-17 15:08:01,278 [Thread-8:11976] [django.request:145] [base:get_response] [WARNING]- Not Found: /auth_login/
